Workbook
Name SINGLE_DRESSER_5313_3D: SUMBER!$A$1:$L$4

Sheet SUMBER
A1: 1 | C1: 1 | D1: FRONT LEG L | E1: 44 | F1: 45 | G1: 743.5 | H1: SL. Mahoni
A2: 2 | C2: 1 | D2: FRONT LEG R | E2: 44 | F2: 45 | G2: 743.5 | H2: SL. Mahoni
A3: 3 | C3: 1 | D3: BACK LEG L | E3: 38 | F3: 104 | G3: 1207 | H3: SL.Mahoni
A4: 4 | C4: 1 | D4: BACK LEG R | E4: 38 | F4: 104 | G4: 1207 | H4: SL.Mahoni
A5: 5 | C5: 1 | D5: FRONT RAIL | E5: 25 | F5: 38 | G5: 509.5 | H5: SL.Mahoni
A6: 6 | C6: 1 | D6: SIDE RAIL L | E6: 32.5 | F6: 38 | G6: 450.5 | H6: SL.Mahoni
A7: 7 | C7: 1 | D7: SIDE RAIL R | E7: 32.5 | F7: 38 | G7: 450.5 | H7: SL.Mahoni
A8: 8 | C8: 1 | D8: BACK RAIL | E8: 38 | F8: 59.5 | G8: 422 | H8: SL.Mahoni
A9: 9 | C9: 1 | D9: STRETCHER SIDE 1 L | E9: 23 | F9: 23 | G9: 515.5 | H9: SL. Mahoni
A10: 10 | C10: 1 | D10: STRETCHER SIDE 2 L | E10: 23 | F10: 23 | G10: 456.5 | H10: SL. Mahoni
A11: 11 | C11: 1 | D11: STRETCHER SIDE 1 R | E11: 23 | F11: 23 | G11: 515.5 | H11: SL. Mahoni
A12: 12 | C12: 1 | D12: STRETCHER SIDE 2 R | E12: 23 | F12: 23 | G12: 456.5 | H12: SL. Mahoni
... A16: 16 | C16: 1 | D16: FRAME BACK REST 4 | E16: 26 | F16: 65 | G16: 433 | H16: SL. Mahoni
A17: 17 | C17: 1 | D17: FRAME BACK REST MIDDLE | E17: 19 | F17: 254 | G17: 455 | H17: SL. Mahoni | I17: 3 Layer
A18: 18 | C18: 1 | D18: FRONT CORNER L | E18: 32 | F18: 43.5 | G18: 106 | H18: SL. Rubber | I18: HARDWOOD
A19: 19 | C19: 1 | D19: FRONT CORNER R | E19: 32 | F19: 43.5 | G19: 106 | H19: SL. Rubber | I19: HARDWOOD
A20: 20 | C20: 1 | D20: BACK CORNER L | E20: 32 | F20: 38 | G20: 139 | H20: SL. Rubber | I20: HARDWOOD
A21: 21 | C21: 1 | D21: BACK CORNER R | E21: 32 | F21: 38 | G21: 139 | H21: SL. Rubber | I21: HARDWOOD
A22: 22 | C22: 1 | D22: BRASS CAP L | E22: 22 | F22: 22 | G22: 432.5 | H22: BRASS
A23: 23 | C23: 1 | D23: BRASS CAP R | E23: 22 | F23: 22 | G23: 432.5 | H23: BRASS
A24: 24 | C24: 1 | D24: BRASS STRETCHER | E24: 19 | F24: 19 | G24: 498.5 | H24: BRASS
A25: 25 | C25: 4 | D25: DOWEL 10X10X30 | E25: 10 | F25: 10 | G25: 30 | H25: SL.White Beech
A26: 26 | C26: 4 | D26: DOWEL 10X10X20 | E26: 10 | F26: 10 | G26: 20 | H26: SL.White Beech

Sheet BOM
A1: Bill Of Material
A2: ( Sample )
D3: Product Name | F3: GABBY
D4: Product Type | F4: HAMBLIN BARSTOOL
D5: Product code | F5: NT-325-2
D6: Size | F6: =": "&U6&" mm x "&V6&" mm x "&W6&" mm" -> : 542 mm x 612 mm x 1215 mm | U6: 542 | V6: 612 | W6: 1215
D7: Tanggal | F7: 4 Oktober 2026
D8: Order | F8: 1
A10: KOMPONEN
A11: No | B11: Code Number | D11: Part Name | E11: ROUGH SIZE | L11: FINISH SIZE | O11: Qty/ Item | P11: Qty/ Order | Q11: M3/ M2 | R11: Material | S11: Note
E12: T | G12: W | I12: L | L12: T | M12: W | N12: L
A13: SUB ASSY BODY
A14: =SUMBER!A1 -> 1 | B14: PF | D14: =SUMBER!D1 -> FRONT LEG L | L14: =SUMBER!E1 -> 44 | M14: =SUMBER!F1 -> 45 | N14: =SUMBER!G1 -> 743.5 | O14: =SUMBER!C1 -> 1 | R14: =SUMBER!H1 -> SL. Mahoni
B15: SF | D15: Core | E15: 5 | F15: =L15+E15 -> 49 | G15: 5 | H15: =G15+M15 -> 50 | I15: 10 | J15: =I15+N15 -> 753.5 | L15: =L14 -> 44 | M15: =M14 -> 45 | N15: =N14 -> 743.5 | O15: =O14 -> 1 | P15: =O15*F$8 -> 1 | Q15: =P15*J15*H15*F15/1000000000 -> 0.001846075 | R15: =R14 -> SL. Mahoni
A17: =SUMBER!A2 -> 2 | B17: PF | D17: =SUMBER!D2 -> FRONT LEG R | L17: =SUMBER!E2 -> 44 | M17: =SUMBER!F2 -> 45 | N17: =SUMBER!G2 -> 743.5 | O17: =SUMBER!C2 -> 1 | R17: =SUMBER!H2 -> SL. Mahoni
B18: SF | D18: Core | E18: 5 | F18: =L18+E18 -> 49 | G18: 5 | H18: =G18+M18 -> 50 | I18: 10 | J18: =I18+N18 -> 753.5 | L18: =L17 -> 44 | M18: =M17 -> 45 | N18: =N17 -> 743.5 | O18: =O17 -> 1 | P18: =O18*F$8 -> 1 | Q18: =P18*J18*H18*F18/1000000000 -> 0.001846075 | R18: =R17 -> SL. Mahoni
A20: =SUMBER!A3 -> 3 | B20: PF | D20: =SUMBER!D3 -> BACK LEG L | L20: =SUMBER!E3 -> 38 | M20: =SUMBER!F3 -> 104 | N20: =SUMBER!G3 -> 1207 | O20: =SUMBER!C3 -> 1 | R20: =SUMBER!H3 -> SL.Mahoni
B21: SF | D21: Core | E21: 5 | F21: =L21+E21 -> 43 | G21: 5 | H21: =G21+M21 -> 109 | I21: 10 | J21: =I21+N21 -> 1217 | L21: =L20 -> 38 | M21: =M20 -> 104 | N21: =N20 -> 1207 | O21: =O20 -> 1 | P21: =O21*F$8 -> 1 | Q21: =P21*J21*H21*F21/1000000000 -> 0.005704079 | R21: =R20 -> SL.Mahoni
A23: =SUMBER!A4 -> 4 | B23: PF | D23: =SUMBER!D4 -> BACK LEG R | L23: =SUMBER!E4 -> 38 | M23: =SUMBER!F4 -> 104 | N23: =SUMBER!G4 -> 1207 | O23: =SUMBER!C4 -> 1 | R23: =SUMBER!H4 -> SL.Mahoni
B24: SF | D24: Core | E24: 5 | F24: =L24+E24 -> 43 | G24: 5 | H24: =G24+M24 -> 109 | I24: 10 | J24: =I24+N24 -> 1217 | L24: =L23 -> 38 | M24: =M23 -> 104 | N24: =N23 -> 1207 | O24: =O23 -> 1 | P24: =O24*F$8 -> 1 | Q24: =P24*J24*H24*F24/1000000000 -> 0.005704079 | R24: =R23 -> SL.Mahoni
A26: =SUMBER!A5 -> 5 | B26: PF | D26: =SUMBER!D5 -> FRONT RAIL | L26: =SUMBER!E5 -> 25 | M26: =SUMBER!F5 -> 38 | N26: =SUMBER!G5 -> 509.5 | O26: =SUMBER!C5 -> 1 | R26: =SUMBER!H5 -> SL.Mahoni
B27: SF | D27: Core | E27: 2 | F27: =L27+E27 -> 27 | G27: 5 | H27: =G27+M27 -> 43 | I27: 10 | J27: =I27+N27 -> 519.5 | L27: =L26 -> 25 | M27: =M26 -> 38 | N27: =N26 -> 509.5 | O27: =O26 -> 1 | P27: =O27*F$8 -> 1 | Q27: =P27*J27*H27*F27/1000000000 -> 0.0006031395 | R27: =R26 -> SL.Mahoni
A29: =SUMBER!A6 -> 6 | B29: PF | D29: =SUMBER!D6 -> SIDE RAIL L | L29: =SUMBER!E6 -> 32.5 | M29: =SUMBER!F6 -> 38 | N29: =SUMBER!G6 -> 450.5 | O29: =SUMBER!C6 -> 1 | R29: =SUMBER!H6 -> SL.Mahoni
B30: SF | D30: Core | E30: 2 | F30: =L30+E30 -> 34.5 | G30: 5 | H30: =G30+M30 -> 43 | I30: 10 | J30: =I30+N30 -> 460.5 | L30: =L29 -> 32.5 | M30: =M29 -> 38 | N30: =N29 -> 450.5 | O30: =O29 -> 1 | P30: =O30*F$8 -> 1 | Q30: =P30*J30*H30*F30/1000000000 -> 0.00068315175 | R30: =R29 -> SL.Mahoni
A32: =SUMBER!A7 -> 7 | B32: PF | D32: =SUMBER!D7 -> SIDE RAIL R | L32: =SUMBER!E7 -> 32.5 | M32: =SUMBER!F7 -> 38 | N32: =SUMBER!G7 -> 450.5 | O32: =SUMBER!C7 -> 1 | R32: =SUMBER!H7 -> SL.Mahoni
B33: SF | D33: Core | E33: 2 | F33: =L33+E33 -> 34.5 | G33: 5 | H33: =G33+M33 -> 43 | I33: 10 | J33: =I33+N33 -> 460.5 | L33: =L32 -> 32.5 | M33: =M32 -> 38 | N33: =N32 -> 450.5 | O33: =O32 -> 1 | P33: =O33*F$8 -> 1 | Q33: =P33*J33*H33*F33/1000000000 -> 0.00068315175 | R33: =R32 -> SL.Mahoni
A35: =SUMBER!A8 -> 8 | B35: PF | D35: =SUMBER!D8 -> BACK RAIL | L35: =SUMBER!E8 -> 38 | M35: =SUMBER!F8 -> 59.5 | N35: =SUMBER!G8 -> 422 | O35: =SUMBER!C8 -> 1 | R35: =SUMBER!H8 -> SL.Mahoni
B36: SF | D36: Core | E36: 2 | F36: =L36+E36 -> 40 | G36: 5 | H36: =G36+M36 -> 64.5 | I36: 10 | J36: =I36+N36 -> 432 | L36: =L35 -> 38 | M36: =M35 -> 59.5 | N36: =N35 -> 422 | O36: =O35 -> 1 | P36: =O36*F$8 -> 1 | Q36: =P36*J36*H36*F36/1000000000 -> 0.00111456 | R36: =R35 -> SL.Mahoni
A38: =SUMBER!A9 -> 9 | B38: PF | D38: =SUMBER!D9 -> STRETCHER SIDE 1 L | L38: =SUMBER!E9 -> 23 | M38: =SUMBER!F9 -> 23 | N38: =SUMBER!G9 -> 515.5 | O38: =SUMBER!C9 -> 1 | R38: =SUMBER!H9 -> SL. Mahoni
B39: SF | D39: Core | E39: 5 | F39: =L39+E39 -> 28 | G39: 5 | H39: =G39+M39 -> 28 | I39: 10 | J39: =I39+N39 -> 525.5 | L39: =L38 -> 23 | M39: =M38 -> 23 | N39: =N38 -> 515.5 | O39: =O38 -> 1 | P39: =O39*F$8 -> 1 | Q39: =P39*J39*H39*F39/1000000000 -> 0.000411992 | R39: =R38 -> SL. Mahoni
A41: =SUMBER!A10 -> 10 | B41: PF | D41: =SUMBER!D10 -> STRETCHER SIDE 2 L | L41: =SUMBER!E10 -> 23 | M41: =SUMBER!F10 -> 23 | N41: =SUMBER!G10 -> 456.5 | O41: =SUMBER!C10 -> 1 | R41: =SUMBER!H10 -> SL. Mahoni
B42: SF | D42: Core | E42: 5 | F42: =L42+E42 -> 28 | G42: 5 | H42: =G42+M42 -> 28 | I42: 10 | J42: =I42+N42 -> 466.5 | L42: =L41 -> 23 | M42: =M41 -> 23 | N42: =N41 -> 456.5 | O42: =O41 -> 1 | P42: =O42*F$8 -> 1 | Q42: =P42*J42*H42*F42/1000000000 -> 0.000365736 | R42: =R41 -> SL. Mahoni
A44: =SUMBER!A11 -> 11 | B44: PF | D44: =SUMBER!D11 -> STRETCHER SIDE 1 R | L44: =SUMBER!E11 -> 23 | M44: =SUMBER!F11 -> 23 | N44: =SUMBER!G11 -> 515.5 | O44: =SUMBER!C11 -> 1 | R44: =SUMBER!H11 -> SL. Mahoni
B45: SF | D45: Core | E45: 5 | F45: =L45+E45 -> 28 | G45: 5 | H45: =G45+M45 -> 28 | I45: 10 | J45: =I45+N45 -> 525.5 | L45: =L44 -> 23 | M45: =M44 -> 23 | N45: =N44 -> 515.5 | O45: =O44 -> 1 | P45: =O45*F$8 -> 1 | Q45: =P45*J45*H45*F45/1000000000 -> 0.000411992 | R45: =R44 -> SL. Mahoni
A47: =SUMBER!A12 -> 12 | B47: PF | D47: =SUMBER!D12 -> STRETCHER SIDE 2 R | L47: =SUMBER!E12 -> 23 | M47: =SUMBER!F12 -> 23 | N47: =SUMBER!G12 -> 456.5 | O47: =SUMBER!C12 -> 1 | R47: =SUMBER!H12 -> SL. Mahoni
B48: SF | D48: Core | E48: 5 | F48: =L48+E48 -> 28 | G48: 5 | H48: =G48+M48 -> 28 | I48: 10 | J48: =I48+N48 -> 466.5 | L48: =L47 -> 23 | M48: =M47 -> 23 | N48: =N47 -> 456.5 | O48: =O47 -> 1 | P48: =O48*F$8 -> 1 | Q48: =P48*J48*H48*F48/1000000000 -> 0.000365736 | R48: =R47 -> SL. Mahoni
A50: =SUMBER!A13 -> 13 | B50: PF | D50: =SUMBER!D13 -> FRAME BACK REST 1 | L50: =SUMBER!E13 -> 23 | M50: =SUMBER!F13 -> 50.5 | N50: =SUMBER!G13 -> 444.5 | O50: =SUMBER!C13 -> 1 | R50: =SUMBER!H13 -> SL.Mahoni
B51: SF | D51: Core | E51: 5 | F51: =L51+E51 -> 28 | G51: 5 | H51: =G51+M51 -> 55.5 | I51: 10 | J51: =I51+N51 -> 454.5 | L51: =L50 -> 23 | M51: =M50 -> 50.5 | N51: =N50 -> 444.5 | O51: =O50 -> 1 | P51: =O51*F$8 -> 1 | Q51: =P51*J51*H51*F51/1000000000 -> 0.000706293 | R51: =R50 -> SL.Mahoni
A53: =SUMBER!A14 -> 14 | B53: PF | D53: =SUMBER!D14 -> FRAME BACK REST 2 | L53: =SUMBER!E14 -> 26 | M53: =SUMBER!F14 -> 68 | N53: =SUMBER!G14 -> 433 | O53: =SUMBER!C14 -> 1 | R53: =SUMBER!H14 -> SL. Mahoni
B54: SF | D54: Core | E54: 5 | F54: =L54+E54 -> 31 | G54: 5 | H54: =G54+M54 -> 73 | I54: 40 | J54: =I54+N54 -> 473 | L54: =L53 -> 26 | M54: =M53 -> 68 | N54: =N53 -> 433 | O54: =O53 -> 1 | P54: =O54*F$8 -> 1 | Q54: =P54*J54*H54*F54/1000000000 -> 0.001070399 | R54: =R53 -> SL. Mahoni
...

Sheet Hardware
A1: Bill of Material
A2: =BOM!A2 -> ( Sample )
B4: Product Name | C4: =BOM!F3 -> GABBY
B5: Code | C5: =BOM!F5 -> NT-325-2
B6: Product Type | C6: =BOM!F4 -> HAMBLIN BARSTOOL
B7: Size | C7: =BOM!F6 -> : 542 mm x 612 mm x 1215 mm
B8: Painting | C8: :
B9: Revisi | C9: =BOM!F7 -> 4 Oktober 2026
B10: Order | C10: 1
A12: No. | B12: No.Code | C12: Nama Barang | D12: Jumlah | E12: Qty/ Order | F12: Satuan | G12: Keterangan | H12: NOTE
A13: ASSY BODY
A14: 1 | B14: RHSSCR00105 | C14: SCREW JP (³) B1025 8MMX1-1/4" BLK OVS | D14: 8 | E14: =D14 -> 8 | F14: Pcs | G14: U/Corner
A15: 3 | B15: RHSSCR00006 | C15: HEX SCREW 1/4"X3" Ø10MM ZINC DMT | D15: 2 | E15: 2 | F15: pcs | G15: u/ Corner Block ke front Leg
A16: 4 | B16: RHSWAS0017 | C16: FLAT WASHER RC0330 5/16"X19X1.5MM ZINC | D16: 4 | E16: =D16*$C$10 -> 4 | F16: pcs | G16: u/ Corner Block ke Leg
A17: 5 | B17: RHSBOL00027 | C17: HEX HEAD BOLT 5/16"X3" Ø13 MM ZINC DMT | D17: 2 | E17: =D17*$C$10 -> 2 | F17: pcs | G17: u/ Corner Block ke back Leg
A18: 6 | B18: RHSWAS0023 | C18: LOCK WASHER 8MM DMT ZINC | D18: 4 | E18: =D18*$C$10 -> 4 | F18: pcs | G18: u/ Corner Block ke Leg
A19: 7 | B19: RHSNUT00030 | C19: PINAPLE NUT D0306 1/4"X10X20MM STEEL | D19: 2 | E19: =D19*$C$10 -> 2 | F19: pcs | G19: u/ Back Leg
A20: 8 | C20: BRASS METAL CAP UK. 22X22X32 | D20: 2 | E20: 2 | F20: pcs | G20: u/ Corner Cap
A21: 9 | C21: BRASS METAL STRETCHER UK. 19X19X498.5 | D21: 1 | E21: 1 | F21: pcs | G21: u/ front leg
A22: FITTING
A23: 1 | B23: RHSGLD00021 | C23: GLIDER BULAT Ø20X6MM DMT BRWN | D23: 4 | E23: =D23 -> 4 | F23: Pcs | G23: U/Leg
A24: UPHOLSTERY
A25: 1 | C25: ROTAN ANYAMAN SINTETIS | D25: 1 | E25: 1 | F25: SET | G25: U/Dudukan
A26: 2
A27: TERBUNGKUS
G29: =BOM!R85 -> Sidoarjo,4 Oktober 2026
B30: Disetujui | D30: Diperiksa | G30: Dibuat
B32: Eris | D32: Mansur | G32: =BOM!R90 -> Alwy

Sheet old
A1: Bill Of Hardware
A2: ( Sample)
B3: ='[1]Bom Material'!D3 -> Product Name | C3: =BOM!F3 -> GABBY
B4: ='[1]Bom Material'!D4 -> Product Type | C4: REGENT CENTER
B5: ='[1]Bom Material'!D5 -> Product code
B6: ='[1]Bom Material'!D6 -> Size | C6: =BOM!F6 -> : 542 mm x 612 mm x 1215 mm
B7: ='[1]Bom Material'!D7 -> Painting
B8: ='[1]Bom Material'!D8 -> Date | C8: 14 November 2024
B9: ='[1]Bom Material'!D9 -> Order | C9: ='[1]Bom Material'!F9 -> 1
A12: No. | B12: Kode Barang | C12: Nama Barang | D12: UKURAN | G12: Jumlah | H12: Qty Order | I12: Satuan. | J12: Keterangan | K12: NOTE
D13: T | E13: L | F13: P
A14: CUSHION
C15: DUDUKAN | D15: 65 | E15: 400 | F15: 413 | G15: 1
A16: 1 | B16: 40000167 | C16: FOAM QUICK DRAY SOFT 50X1250X2350MM | D16: 50 | E16: =E15 -> 400 | F16: =F15 -> 413 | G16: =G15*L16 -> 0 | H16: =D16*E16*F16*G16/1000000000 -> 0 | I16: M3 | J16: U/ Cushion Dudukan | L16: 0
A17: =A16+1 -> 2 | B17: 40000170 | C17: FOAM QUICK DRAY MEDIUM 50X1250X2350MM | D17: 50 | E17: =E15 -> 400 | F17: =F15 -> 413 | G17: =G15*L17 -> 1 | H17: =D17*E17*F17*G17/1000000000 -> 0.00826 | I17: M3 | J17: U/ Cushion Dudukan | L17: 1
A18: =A17+1 -> 3 | B18: 40000198 | C18: FOAM QUICK DRAY FIRM 10X1250X2350MM | D18: 10 | E18: =E15 -> 400 | F18: =F15 -> 413 | G18: =G15*L18 -> 1 | H18: =D18*E18*F18*G18/1000000000 -> 0.001652 | I18: M3 | J18: U/ Cushion Dudukan | L18: 1
A19: =A18+1 -> 4 | B19: RHUBSA00008 | C19: DACRON ARNR 50Z LEBAR 2 M | D19: 1 | E19: =D15*2+E15 -> 530 | F19: =D15*2+F15 -> 543 | G19: =G15*L19 -> 1 | H19: =0.129*2 -> 0.258 | I19: Kg | J19: U/ Cushion Dudukan | L19: 1
A20: =A19+1 -> 5 | C20: FABRIC | D20: 1 | E20: =E15+30+D15+D15 -> 560 | F20: =F15+30+D15+D15 -> 573 | G20: =G15 -> 1 | H20: =G15*N20/1000 -> 0.2865 | I20: M | J20: U/ Cover Atas | L20: 1400 | M20: 2 | N20: =F20/M20 -> 286.5
